<?xml version="1.0"?>
<robot xmlns:xacro="http://www.ros.org/wiki/xacro" >

    <xacro:include filename="inertial_macros.xacro"/>

    <material name="white">
        <color rgba= "1 1 1 1" />
    </material>

<material name="orange">
        <color rgba= "1 0.3 0.1 1" />
    </material>
    
<material name="blue">
        <color rgba= "0.2 0.2 1 1" />
    </material>

<material name="black">
        <color rgba= "0 0 0 0" />
    </material>

<material name="red">
        <color rgba= "1 0 0 1" />
    </material>

 <!-- BASE LINK-->
    <link name ="base_link">

    </link>

<!--BASE FOOTPRINT LINK-->
    <joint name="base_footprint_joint" type="fixed">
        <parent link="base_link"/>
        <child link="base_footprint"/>
        <origin xyz="0 0 0" rpy="0 0 0"/>
    </joint>

    <link name="base_footprint">
    </link>



    <!--CHASSIS LINK-->
    <joint name="chassis_joint" type="fixed">
        <parent link="base_link"/>
        <child link="chassis"/>
        <origin xyz= "-0.1 0 0"/>
    </joint>

    <link name="chassis">
        <visual>
            <origin xyz="0.15 0 0.075"/>
            <geometry>
                <box size="0.3 0.3 0.15"/>
                </geometry>
            <material name = "white"/>

        </visual>
        <collision>
            
            <origin xyz="0.15 0 0.075"/>
            <geometry>
                <box size="0.3 0.3 0.15"/>
            </geometry>
        </collision>
        <xacro:inertial_box mass="0.5" x="0.3" y="0.3" z="0.15">
            <origin xyz= "0.15 0 0.075" rpy="0 0 0" />
        </xacro:inertial_box>

    </link>

    <gazebo reference="chassis">
        <material>Gazebo/White</material>
    </gazebo>


    <!--LEFT WHEEL LINK-->

    <joint name="left_wheel_joint" type="continuous">
        <parent link="base_link"/>
        <child link="left_wheel"/>
        <origin xyz="0 0.175 0" rpy="-${pi/2} 0 0"/>
        <axis xyz= "0 0 1"/>
     </joint>

    <link name= "left_wheel">
        <visual>
            <geometry>
                <cylinder radius="0.05" length="0.04"/>

            </geometry>
            <material name="blue"/>
        </visual>

        <collision>
            <geometry>
                <cylinder radius="0.05" length="0.04"/>

            </geometry>
        
        </collision>
        <xacro:inertial_cylinder mass="0.1" radius="0.05" length="0.04">
            <origin xyz= "0 0 0" rpy="0 0 0" />
        </xacro:inertial_cylinder>
    </link>


      <gazebo reference="left_wheel">
        <material>Gazebo/Blue</material>
    </gazebo>
    <!--RIGHT WHEEL LINK-->

    <joint name="right_wheel_joint" type="continuous">
        <parent link="base_link"/>
        <child link="right_wheel"/>
        <origin xyz="0 -0.175 0" rpy="${pi/2} 0 0"/>
        <axis xyz= "0 0 -1"/>
     </joint>

    <link name= "right_wheel">
        <visual>
            <geometry>
                <cylinder radius="0.05" length="0.04"/>

            </geometry>
            <material name="blue"/>
        </visual>
        <collision>
            <geometry>
                <cylinder radius="0.05" length="0.04"/>

            </geometry>
    
        </collision>
        <xacro:inertial_cylinder mass="0.1" radius="0.05" length="0.04">
            <origin xyz= "0 0 0" rpy="0 0 0" />
        </xacro:inertial_cylinder>
    </link>

      <gazebo reference="right_wheel">
        <material>Gazebo/Blue</material>
    </gazebo>

    <!--CASTER WHEEL LINK-->

    <joint name="caster_wheel_joint" type="fixed">
        <parent link= "chassis"/>
        <child link="caster_wheel"/>
        <origin xyz="0.24 0 0"/>
    </joint>

     <link name="caster_wheel">
        <visual>
            <geometry>
                <sphere radius="0.05"/> 
            </geometry>
            <material name="black"/>
        </visual>
        <collision>
            <geometry>
                <sphere radius="0.05"/> 
            </geometry>
        
        </collision>
        <xacro:inertial_sphere mass="0.1" radius="0.05">
            <origin xyz= "0 0 0" rpy="0 0 0" />
        </xacro:inertial_sphere>
    </link>

    <gazebo reference="caster_wheel">
        <material>Gazebo/Black</material>
        <mu1 value="0.001"/>
        <mu2 value="0.001"/>
    </gazebo>

  
 <!--LIDAR-->



    <joint name="laser_joint" type="fixed">
        <parent link="chassis"/>
        <child link="laser_frame"/>
        <origin xyz="0.122 0 0.212" rpy="0 0 0"/>
    </joint>

    <link name="laser_frame">
        <visual>
            <geometry>
                <cylinder radius="0.05" length="0.04"/>
            </geometry>
            <material name="black"/>
        </visual>
        <visual>
            <origin xyz="0 0 -0.05"/>
            <geometry>
                <cylinder radius="0.01" length="0.1"/>
            </geometry>
            <material name="black"/>
        </visual>
        <collision>
            <geometry>
                <cylinder radius="0.05" length="0.04"/>
            </geometry>
        </collision>
        <xacro:inertial_cylinder mass="0.1" length="0.04" radius="0.05">
            <origin xyz="0 0 0" rpy="0 0 0"/>
        </xacro:inertial_cylinder>
    </link>



    <gazebo reference="laser_frame">
        <material>Gazebo/Black</material>

        <sensor name="laser" type="ray">
            <pose> 0 0 0 0 0 0 </pose>
            <visualize>true</visualize>
            <update_rate>10</update_rate>
            <ray>
                <scan>
                    <horizontal>
                        <samples>360</samples>
                        <min_angle>-3.14</min_angle>
                        <max_angle>3.14</max_angle>
                    </horizontal>
                </scan>
                <range>
                    <min>0.3</min>
                    <max>12</max>
                </range>
            </ray>
            <plugin name="laser_controller" filename="libgazebo_ros_ray_sensor.so">
                <ros>
                    <argument>~/out:=scan</argument>
                </ros>
                <output_type>sensor_msgs/LaserScan</output_type>
                <frame_name>laser_frame</frame_name>
            </plugin>
        </sensor>
    </gazebo>
</robot>